Workbook

Sheet Panduan & Ringkasan
A1: Kamus Slang Hook Konten Kreator
A2: Dataset untuk melatih AI pembuat brief & hook konten (TikTok, Reels, Shorts). Disusun Oktober 2026.
A4: Isi Workbook
A5: Kamus Slang | B5: Daftar utama: kata, arti, fungsi hook, contoh kalimat, niche, tone, status tren, keamanan brand, catatan untuk AI.
A6: Template Hook | B6: Rumus hook siap isi yang menggabungkan slang dengan struktur hook yang terbukti.
A7: Data Training | B7: Pasangan instruction → output yang tersusun otomatis dari Kamus Slang (rumus). Bisa diekspor ke CSV/JSONL untuk fine-tuning atau few-shot.
A9: Arti Status Tren
A10: Evergreen | B10: Aman dipakai kapan saja; sudah jadi bahasa sehari-hari.
A11: Masih Tren | B11: Populer beberapa tahun terakhir dan masih sering dipakai.
A12: Viral 2025–26 | B12: Sedang naik; efektif sekarang tapi umurnya pendek. Cek ulang tiap 3 bulan.
A13: Mulai Basi | B13: Pernah viral, sekarang terasa jadul. Pakai hanya untuk nostalgia/ironi.
A15: Arti Keamanan Brand
A16: Aman | B16: Boleh untuk semua brand dan audiens.
A17: Kasar Ringan | B17: Plesetan umpatan atau ungkapan kasar ringan; hindari untuk brand formal & audiens anak.
A18: Sensitif | B18: Rawan disalahartikan (isu mental, fisik, judi online, merendahkan orang). AI wajib baca kolom Catatan.
A20: Aturan untuk AI
A21: 1. Taruh slang di 3 detik / 1 kalimat pertama, lalu langsung beri janji manfaat yang spesifik (angka, harga, waktu).
A22: 2. Maksimal 1–2 slang per hook; terlalu banyak terdengar cringe dan maksa.
A23: 3. Sesuaikan slang dengan niche dan usia audiens (lihat kolom Cocok untuk Niche & Status Tren).
A24: 4. Setiap janji di hook ("tonton sampai habis", "plot twist") harus dibayar di isi video.
A25: 5. Jangan pakai slang berstatus Sensitif tanpa mengikuti catatannya; jangan pakai Kasar Ringan untuk brand formal.
A27: Ringkasan per Kategori
A28: Kategori | C28: Jumlah
A29: Ajakan & CTA | C29: =COUNTIF('Kamus Slang'!$D$2:$D$132,A29) -> 7
A30: Cuan & Belanja | C30: =COUNTIF('Kamus Slang'!$D$2:$D$132,A30) -> 8
A31: Format Konten | C31: =COUNTIF('Kamus Slang'!$D$2:$D$132,A31) -> 10
A32: Gen Z English | C32: =COUNTIF('Kamus Slang'!$D$2:$D$132,A32) -> 22
A33: Hype & Pujian | C33: =COUNTIF('Kamus Slang'!$D$2:$D$132,A33) -> 24
A34: Kritik & Negatif | C34: =COUNTIF('Kamus Slang'!$D$2:$D$132,A34) -> 11
A35: Meme & Viral | C35: =COUNTIF('Kamus Slang'!$D$2:$D$132,A35) -> 13
A36: Penasaran & Rahasia | C36: =COUNTIF('Kamus Slang'!$D$2:$D$132,A36) -> 10
A37: Relatable & Perasaan | C37: =COUNTIF('Kamus Slang'!$D$2:$D$132,A37) -> 15
A38: Sapaan & Panggilan | C38: =COUNTIF('Kamus Slang'!$D$2:$D$132,A38) -> 4
A39: Singkatan | C39: =COUNTIF('Kamus Slang'!$D$2:$D$132,A39) -> 7
A40: Total | C40: =SUM(C29:C39) -> 131
A42: Catatan sumber
A43: Disusun dari pengamatan umum bahasa konten TikTok/Instagram Indonesia, ditambah istilah viral 2026 (six seven, aura farming, clock it) yang dirangkum Popbela: popbela.com/career/inspiration/mengenal-istilah-six-seven-hingga-clock-it-00-vp6g8-pm1gfw. Status tren adalah penilaian per Oktober 2026 dan perlu diperbarui berkala.

Sheet Kamus Slang
A1: ID | B1: Kata / Frasa | C1: Variasi Penulisan | D1: Kategori | E1: Arti / Makna | F1: Fungsi Hook | G1: Contoh Penggunaan (Hook) | H1: Cocok untuk Niche | I1: Tone | J1: Status Tren | K1: Keamanan Brand | L1: Catatan untuk AI
A2: SLG-001 | B2: Gas | C2: gaskeun, gass, gaspol | D2: Ajakan & CTA | E2: Ayo, lanjut, langsung jalan | F2: Ajakan/CTA | G2: Gas, kita coba resep viral ini dan buktikan hasilnya. | H2: Semua niche | I2: Semangat | J2: Evergreen | K2: Aman
A3: SLG-002 | B3: Jangan di-skip | C3: jangan skip, wajib nonton | D3: Ajakan & CTA | E3: Ajakan agar video ditonton | F3: Ajakan/CTA | G3: Jangan di-skip, ini penting buat kamu yang mau lulus tepat waktu. | H3: Edukasi, Semua niche | I3: Mendesak | J3: Evergreen | K3: Aman
A4: SLG-003 | B4: Mutualan | C4: mutual | D4: Ajakan & CTA | E4: Saling follow | F4: Ajakan/CTA | G4: Mutualan yuk, sesama anak desain. | H4: Sosmed | I4: Akrab | J4: Evergreen | K4: Aman
A5: SLG-004 | B5: Save dulu | C5: simpan dulu | D5: Ajakan & CTA | E5: Ajakan menyimpan konten | F5: Ajakan/CTA | G5: Save dulu, nanti pasti kepake pas ngerjain skripsi. | H5: Edukasi, Tips | I5: Akrab | J5: Evergreen | K5: Aman | L5: Menaikkan save rate.
A6: SLG-005 | B6: Stop scroll | C6: berhenti scroll, stop dulu | D6: Ajakan & CTA | E6: Ajakan berhenti menggulir layar | F6: Ajakan/CTA | G6: Stop scroll kalau kamu masih nyimpen semua uang di satu rekening. | H6: Semua niche | I6: Mendesak | J6: Evergreen | K6: Aman
A7: SLG-006 | B7: Tonton sampai habis | C7: nonton sampe abis | D7: Ajakan & CTA | E7: Ajakan menonton video sampai selesai | F7: Ajakan/CTA | G7: Tonton sampai habis, bagian terakhir yang paling penting. | H7: Semua niche | I7: Mendesak | J7: Evergreen | K7: Aman | L7: Harus ditepati dengan payoff di akhir video.
A8: SLG-007 | B8: Wajib tau | C8: wajib tahu, wajib coba | D8: Ajakan & CTA | E8: Harus diketahui atau dicoba | F8: Peringatan/FOMO | G8: Anak kos wajib tau trik masak nasi tanpa rice cooker ini. | H8: Tips, Edukasi | I8: Mendesak | J8: Evergreen | K8: Aman
A9: SLG-008 | B9: Boncos | C9: boncos parah | D9: Cuan & Belanja | E9: Rugi | F9: Peringatan/FOMO | G9: Bisnis boncos gara-gara 3 kesalahan ini. | H9: Bisnis, Finansial | I9: Mengingatkan | J9: Evergreen | K9: Aman
A10: SLG-009 | B10: Cuan | C10: cuan tipis-tipis | D10: Cuan & Belanja | E10: Untung atau penghasilan | F10: Klaim Nilai/Manfaat | G10: Cuan pertamaku dari freelance desain, ini caranya. | H10: Bisnis, Finansial, Karier | I10: Semangat | J10: Evergreen | K10: Aman | L10: Hindari janji penghasilan pasti.
A11: SLG-010 | B11: Mendang-mending | C11: kaum mendang-mending | D11: Cuan & Belanja | E11: Orang yang selalu membandingkan opsi demi yang paling hemat | F11: Relate/Empati | G11: Buat kaum mendang-mending, ini perbandingan HP 2 jutaan paling jujur. | H11: Tech, Belanja, Finansial | I11: Jenaka | J11: Masih Tren | K11: Aman
A12: SLG-011 | B12: Racun | C12: ngeracunin, keracunan, racun Shopee | D12: Cuan & Belanja | E12: Produk yang bikin penonton tergoda membeli | F12: Klaim Nilai/Manfaat | G12: Siap-siap keracunan, ini 5 barang Shopee di bawah 50 ribu yang kepake banget. | H12: Affiliate, Review, Haul | I12: Heboh, akrab | J12: Evergreen | K12: Aman | L12: Sangat cocok untuk konten affiliate.
A13: SLG-012 | B13: Self reward | C13: self-reward | D13: Cuan & Belanja | E13: Hadiah untuk diri sendiri | F13: Klaim Nilai/Manfaat | G13: Self reward tapi dompet tetap aman, ini caranya. | H13: Belanja, Finansial | I13: Hangat | J13: Evergreen | K13: Aman
A14: SLG-013 | B14: Sultan | C14: ala sultan | D14: Cuan & Belanja | E14: Orang kaya atau gaya hidup mewah | F14: Klaim Nilai/Manfaat | G14: Makan ala sultan cuma modal 20 ribu. | H14: Kuliner, Finansial | I14: Jenaka | J14: Evergreen | K14: Aman | L14: Kontras "sultan" + harga murah sangat efektif.
A15: SLG-014 | B15: Tipis-tipis | C15: tipis tipis | D15: Cuan & Belanja | E15: Sedikit demi sedikit | F15: Klaim Nilai/Manfaat | G15: Cuan tipis-tipis dari jualan es teh depan kampus. | H15: Bisnis, UMKM | I15: Santai | J15: Evergreen | K15: Aman
A16: SLG-015 | B16: Worth it | C16: worthit, worth it gak? | D16: Cuan & Belanja | E16: Sepadan dengan harga atau usaha | F16: Bikin Penasaran | G16: Worth it gak sih beli iPhone bekas di 2026? | H16: Review, Tech, Belanja | I16: Kritis | J16: Evergreen | K16: Aman | L16: Format pertanyaan menahan penonton sampai jawaban.
A17: SLG-016 | B17: Day in my life | C17: DITL, a day in my life | D17: Format Konten | E17: Rutinitas satu hari | F17: Relate/Empati | G17: A day in my life sebagai mahasiswa teknik sambil freelance. | H17: Lifestyle, Karier | I17: Santai | J17: Evergreen | K17: Aman
A18: SLG-017 | B18: FYP | C18: fyp, masuk FYP | D18: Format Konten | E18: For You Page; halaman rekomendasi TikTok | F18: Klaim Nilai/Manfaat | G18: Rahasia konten masuk FYP padahal akun baru. | H18: Sosmed, Bisnis | I18: Yakin | J18: Evergreen | K18: Aman
A19: SLG-018 | B19: GRWM | C19: get ready with me | D19: Format Konten | E19: Format video bersiap-siap sambil bercerita | F19: Bikin Penasaran | G19: GRWM ke kampus sambil cerita dosen paling killer. | H19: Beauty, Storytime | I19: Akrab | J19: Evergreen | K19: Aman
A20: SLG-019 | B20: Haul | C20: haul Shopee | D20: Format Konten | E20: Video memamerkan hasil belanja | F20: Klaim Nilai/Manfaat | G20: Haul Shopee 11.11, ada yang zonk ada yang worth it. | H20: Affiliate, Belanja | I20: Antusias | J20: Evergreen | K20: Aman
A21: SLG-020 | B21: Ngonten | C21: bikin konten | D21: Format Konten | E21: Membuat konten | F21: Relate/Empati | G21: Ngonten sambil kuliah, ini jadwal harianku. | H21: Lifestyle, Kreator | I21: Santai | J21: Evergreen | K21: Aman
A22: SLG-021 | B22: OOTD | C22: outfit of the day | D22: Format Konten | E22: Pakaian yang dipakai hari ini | F22: Klaim Nilai/Manfaat | G22: OOTD ngampus seminggu cuma pakai 5 baju. | H22: Fashion | I22: Santai | J22: Evergreen | K22: Aman
A23: SLG-022 | B23: POV | C23: pov: | D23: Format Konten | E23: Sudut pandang; mengajak penonton membayangkan diri di situasi tertentu | F23: Relate/Empati | G23: POV: kamu anak teknik yang tiba-tiba disuruh bikin poster acara. | H23: Komedi, Storytime | I23: Jenaka | J23: Evergreen | K23: Aman | L23: Biasanya ditulis sebagai teks di layar.
A24: SLG-023 | B24: Starter pack | C24: starterpack | D24: Format Konten | E24: Kumpulan barang atau ciri khas suatu tipe orang | F24: Humor/Absurd | G24: Starter pack mahasiswa baru yang pasti kebeli di minggu pertama. | H24: Komedi, Lifestyle, Affiliate | I24: Jenaka | J24: Evergreen | K24: Aman
A25: SLG-024 | B25: Tier list | C25: tierlist | D25: Format Konten | E25: Daftar peringkat S-A-B-C | F25: Kontroversi/Opini | G25: Tier list jajanan Aceh versi aku, siap-siap debat. | H25: Kuliner, Gaming, Opini | I25: Berani | J25: Evergreen | K25: Aman
A26: SLG-025 | B26: Unboxing | C26: unbox | D26: Format Konten | E26: Membuka kemasan produk di depan kamera | F26: Bikin Penasaran | G26: Unboxing HP 2 jutaan, kameranya bikin kaget. | H26: Tech, Review, Affiliate | I26: Antusias | J26: Evergreen | K26: Aman
A27: SLG-026 | B27: Ate | C27: ate, ate no crumbs | D27: Gen Z English | E27: Sangat berhasil atau memukau dalam penampilan | F27: Validasi/Pujian | G27: Dia ate banget di panggung wisuda kemarin. | H27: Fashion, Hiburan | I27: Heboh | J27: Masih Tren | K27: Aman
A28: SLG-027 | B28: Beige flag | C28: beige flag | D28: Gen Z English | E28: Kebiasaan aneh yang netral, bukan baik bukan buruk | F28: Humor/Absurd | G28: Beige flag pacarku: makan bakso tanpa kuah. | H28: Komedi, Relationship | I28: Jenaka | J28: Masih Tren | K28: Aman
A29: SLG-028 | B29: Canon event | C29: canon event | D29: Gen Z English | E29: Pengalaman yang "pasti" dialami semua orang dan membentuk diri | F29: Relate/Empati | G29: Dimarahin dosen pas presentasi itu canon event anak kuliahan. | H29: Komedi, Storytime | I29: Jenaka | J29: Viral 2025–26 | K29: Aman
A30: SLG-029 | B30: Clock it | C30: clocked | D30: Gen Z English | E30: Menyadari atau "menangkap basah" sesuatu; juga pujian untuk detail yang tepat | F30: Validasi/Pujian | G30: Clock it: detail kecil ini yang bikin desainmu keliatan pro. | H30: Desain, Fashion, Komedi | I30: Percaya diri | J30: Viral 2025–26 | K30: Aman
A31: SLG-030 | B31: Delulu | C31: delulu is the solulu | D31: Gen Z English | E31: Delusional; dipakai jenaka untuk optimisme berlebihan | F31: Humor/Absurd | G31: Delulu is the solulu: cara manifest target 2027 versi realistis. | H31: Self-improvement, Komedi | I31: Jenaka | J31: Masih Tren | K31: Aman
A32: SLG-031 | B32: Hot take | C32: hot take | D32: Gen Z English | E32: Opini panas atau kontroversial | F32: Kontroversi/Opini | G32: Hot take: IPK tinggi gak menjamin dapat kerja. | H32: Karier, Opini | I32: Berani | J32: Masih Tren | K32: Aman
A33: SLG-032 | B33: I know ball | C33: i know ball | D33: Gen Z English | E33: Klaim jenaka sebagai ahli di suatu bidang | F33: Humor/Absurd | G33: Aku bukan chef, tapi I know ball soal nasi goreng. | H33: Komedi, Opini | I33: Jenaka | J33: Viral 2025–26 | K33: Aman | L33: Lebih dikenal audiens yang aktif di internet global.
A34: SLG-033 | B34: Jujurly | C34: jujurli | D34: Gen Z English | E34: Jujur saja (gabungan "jujur" + "-ly") | F34: Klaim Nilai/Manfaat | G34: Jujurly, ini skincare termurah yang beneran ngefek di aku. | H34: Review, Beauty | I34: Akrab | J34: Masih Tren | K34: Aman | L34: Memberi kesan review jujur.
A35: SLG-034 | B35: Kalcer | C35: culture | D35: Gen Z English | E35: Bergaya sesuai budaya tren anak muda kota | F35: Validasi/Pujian | G35: Outfit kalcer buat nongkrong, semuanya di bawah 200 ribu. | H35: Fashion, Lifestyle | I35: Santai | J35: Masih Tren | K35: Aman
A36: SLG-035 | B36: Literally | C36: literali | D36: Gen Z English | E36: Benar-benar (penekan kata) | F36: Klaim Nilai/Manfaat | G36: Ini literally serum paling worth it yang pernah aku coba. | H36: Review, Beauty | I36: Antusias | J36: Evergreen | K36: Aman | L36: Jangan diulang lebih dari sekali dalam satu kalimat.
A37: SLG-036 | B37: Lock in | C37: locked in, mode lock in | D37: Gen Z English | E37: Fokus total, serius mengerjakan sesuatu | F37: Ajakan/CTA | G37: Mode lock in: 4 jam belajar tanpa distraksi pakai cara ini. | H37: Produktivitas, Edukasi | I37: Semangat | J37: Viral 2025–26 | K37: Aman
A38: SLG-037 | B38: Lowkey | C38: lowkey, highkey | D38: Gen Z English | E38: Diam-diam atau sedikit (lowkey); terang-terangan (highkey) | F38: Relate/Empati | G38: Lowkey ini kebiasaan kecil yang bikin hidup lebih rapi. | H38: Lifestyle, Produktivitas | I38: Santai | J38: Masih Tren | K38: Aman
A39: SLG-038 | B39: Main character | C39: main character energy | D39: Gen Z English | E39: Merasa jadi tokoh utama; percaya diri | F39: Validasi/Pujian | G39: Jalan sore di pantai biar berasa main character. | H39: Travel, Lifestyle | I39: Dreamy | J39: Masih Tren | K39: Aman
A40: SLG-039 | B40: No cap | C40: no cap | D40: Gen Z English | E40: Tanpa bohong, serius | F40: Klaim Nilai/Manfaat | G40: No cap, rasanya kayak restoran bintang 5. | H40: Kuliner, Review | I40: Yakin | J40: Masih Tren | K40: Aman
...

Sheet Template Hook
A1: Tipe Hook | B1: Rumus | C1: Template Isian | D1: Contoh Jadi
A2: Penasaran | B2: [Slang penasaran] + [objek] + [hasil spesifik] | C2: Aku spill [produk] yang bikin [hasil] cuma dalam [waktu]. | D2: Aku spill sabun cuci muka yang bikin jerawat kempes cuma dalam 5 hari.
A3: Penasaran | B3: Ternyata / Nyesel baru tau + [fakta] | C3: Nyesel baru tau [fakta/fitur] ini sekarang. | D3: Nyesel baru tau Canva punya fitur hapus background gratis.
A4: Penasaran | B4: Hidden gem + [lokasi] + [pembeda] | C4: Hidden gem [kategori] di [kota] yang belum banyak orang tahu. | D4: Hidden gem mie Aceh di Banda Aceh yang belum banyak orang tahu.
A5: Pertanyaan | B5: Worth it gak sih + [keputusan] | C5: Worth it gak sih [beli/lakukan X] di [tahun]? | D5: Worth it gak sih beli laptop bekas buat kuliah desain di 2026?
A6: Relate | B6: POV: + [situasi spesifik audiens] | C6: POV: kamu [identitas audiens] yang [masalah lucu]. | D6: POV: kamu anak teknik yang disuruh bikin poster H-1 acara.
A7: Relate | B7: Aku doang yang + [kebiasaan]? | C7: Aku doang yang [kebiasaan aneh tapi umum]? | D7: Aku doang yang buka aplikasi belanja tiap gabut padahal gak ada duit?
A8: Relate | B8: Buat kamu yang [kondisi slang] + [solusi] | C8: Buat kamu yang [mager/gabut/insecure], coba [solusi]. | D8: Buat kamu yang mager olahraga, coba gerakan 5 menit ini.
A9: Kontras Nilai | B9: [Slang mewah] + modal [harga murah] | C9: [Hasil] ala sultan cuma modal [harga]. | D9: Makan steak ala sultan cuma modal 25 ribu.
A10: Kontras Nilai | B10: [Slang jelek] + juga bisa + [hasil bagus] | C10: [HP/alat] kentang juga bisa [hasil] kayak gini. | D10: HP kentang juga bisa bikin video sinematik kayak gini.
A11: Peringatan | B11: [Angka] red flag + [konteks] | C11: [Angka] red flag pas [aktivitas] yang sering diabaikan. | D11: 3 red flag pas terima klien freelance yang sering diabaikan.
A12: Peringatan | B12: Stop scroll kalau kamu masih + [kesalahan] | C12: Stop scroll kalau kamu masih [kesalahan umum]. | D12: Stop scroll kalau kamu masih ngedit foto pakai filter bawaan.
... A19: Transformasi | B19: Glow up + [objek] + modal [harga/waktu] | C19: Glow up [objek] cuma modal [harga/waktu]. | D19: Glow up feed Instagram cuma modal 1 jam pakai template ini.

Sheet Data Training
A1: ID | B1: Instruction (input untuk AI) | C1: Output (contoh hook) | D1: Kata Kunci
A2: ='Kamus Slang'!A2 -> SLG-001 | B2: ="Buat hook konten dengan fungsi "&LOWER('Kamus Slang'!F2)&" untuk niche "&'Kamus Slang'!H2&" menggunakan slang '"&'Kamus Slang'!B2&"' (arti: "&'Kamus Slang'!E2&"). Tone: "&LOWER('Kamus Slang'!I2)&"." -> Buat hook konten dengan fungsi ajakan/cta untuk niche Semua niche menggunakan slang 'Gas' (arti: Ayo, lanjut, langsung jalan). Tone: semangat. | C2: ='Kamus Slang'!G2 -> Gas, kita coba resep viral ini dan buktikan hasilnya. | D2: ='Kamus Slang'!B2 -> Gas
A3: ='Kamus Slang'!A3 -> SLG-002 | B3: ="Buat hook konten dengan fungsi "&LOWER('Kamus Slang'!F3)&" untuk niche "&'Kamus Slang'!H3&" menggunakan slang '"&'Kamus Slang'!B3&"' (arti: "&'Kamus Slang'!E3&"). Tone: "&LOWER('Kamus Slang'!I3)&"." -> Buat hook konten dengan fungsi ajakan/cta untuk niche Edukasi, Semua niche menggunakan slang 'Jangan di-skip' (arti: Ajakan agar video ditonton). Tone: mendesak. | C3: ='Kamus Slang'!G3 -> Jangan di-skip, ini penting buat kamu yang mau lulus tepat waktu. | D3: ='Kamus Slang'!B3 -> Jangan di-skip
A4: ='Kamus Slang'!A4 -> SLG-003 | B4: ="Buat hook konten dengan fungsi "&LOWER('Kamus Slang'!F4)&" untuk niche "&'Kamus Slang'!H4&" menggunakan slang '"&'Kamus Slang'!B4&"' (arti: "&'Kamus Slang'!E4&"). Tone: "&LOWER('Kamus Slang'!I4)&"." -> Buat hook konten dengan fungsi ajakan/cta untuk niche Sosmed menggunakan slang 'Mutualan' (arti: Saling follow). Tone: akrab. | C4: ='Kamus Slang'!G4 -> Mutualan yuk, sesama anak desain. | D4: ='Kamus Slang'!B4 -> Mutualan
A5: ='Kamus Slang'!A5 -> SLG-004 | B5: ="Buat hook konten dengan fungsi "&LOWER('Kamus Slang'!F5)&" untuk niche "&'Kamus Slang'!H5&" menggunakan slang '"&'Kamus Slang'!B5&"' (arti: "&'Kamus Slang'!E5&"). Tone: "&LOWER('Kamus Slang'!I5)&"." -> Buat hook konten dengan fungsi ajakan/cta untuk niche Edukasi, Tips menggunakan slang 'Save dulu' (arti: Ajakan menyimpan konten). Tone: akrab. | C5: ='Kamus Slang'!G5 -> Save dulu, nanti pasti kepake pas ngerjain skripsi. | D5: ='Kamus Slang'!B5 -> Save dulu
A6: ='Kamus Slang'!A6 -> SLG-005 | B6: ="Buat hook konten dengan fungsi "&LOWER('Kamus Slang'!F6)&" untuk niche "&'Kamus Slang'!H6&" menggunakan slang '"&'Kamus Slang'!B6&"' (arti: "&'Kamus Slang'!E6&"). Tone: "&LOWER('Kamus Slang'!I6)&"." -> Buat hook konten dengan fungsi ajakan/cta untuk niche Semua niche menggunakan slang 'Stop scroll' (arti: Ajakan berhenti menggulir layar). Tone: mendesak. | C6: ='Kamus Slang'!G6 -> Stop scroll kalau kamu masih nyimpen semua uang di satu rekening. | D6: ='Kamus Slang'!B6 -> Stop scroll
A7: ='Kamus Slang'!A7 -> SLG-006 | B7: ="Buat hook konten dengan fungsi "&LOWER('Kamus Slang'!F7)&" untuk niche "&'Kamus Slang'!H7&" menggunakan slang '"&'Kamus Slang'!B7&"' (arti: "&'Kamus Slang'!E7&"). Tone: "&LOWER('Kamus Slang'!I7)&"." -> Buat hook konten dengan fungsi ajakan/cta untuk niche Semua niche menggunakan slang 'Tonton sampai habis' (arti: Ajakan menonton video sampai selesai). Tone: mendesak. | C7: ='Kamus Slang'!G7 -> Tonton sampai habis, bagian terakhir yang paling penting. | D7: ='Kamus Slang'!B7 -> Tonton sampai habis
A8: ='Kamus Slang'!A8 -> SLG-007 | B8: ="Buat hook konten dengan fungsi "&LOWER('Kamus Slang'!F8)&" untuk niche "&'Kamus Slang'!H8&" menggunakan slang '"&'Kamus Slang'!B8&"' (arti: "&'Kamus Slang'!E8&"). Tone: "&LOWER('Kamus Slang'!I8)&"." -> Buat hook konten dengan fungsi peringatan/fomo untuk niche Tips, Edukasi menggunakan slang 'Wajib tau' (arti: Harus diketahui atau dicoba). Tone: mendesak. | C8: ='Kamus Slang'!G8 -> Anak kos wajib tau trik masak nasi tanpa rice cooker ini. | D8: ='Kamus Slang'!B8 -> Wajib tau
A9: ='Kamus Slang'!A9 -> SLG-008 | B9: ="Buat hook konten dengan fungsi "&LOWER('Kamus Slang'!F9)&" untuk niche "&'Kamus Slang'!H9&" menggunakan slang '"&'Kamus Slang'!B9&"' (arti: "&'Kamus Slang'!E9&"). Tone: "&LOWER('Kamus Slang'!I9)&"." -> Buat hook konten dengan fungsi peringatan/fomo untuk niche Bisnis, Finansial menggunakan slang 'Boncos' (arti: Rugi). Tone: mengingatkan. | C9: ='Kamus Slang'!G9 -> Bisnis boncos gara-gara 3 kesalahan ini. | D9: ='Kamus Slang'!B9 -> Boncos
A10: ='Kamus Slang'!A10 -> SLG-009 | B10: ="Buat hook konten dengan fungsi "&LOWER('Kamus Slang'!F10)&" untuk niche "&'Kamus Slang'!H10&" menggunakan slang '"&'Kamus Slang'!B10&"' (arti: "&'Kamus Slang'!E10&"). Tone: "&LOWER('Kamus Slang'!I10)&"." -> Buat hook konten dengan fungsi klaim nilai/manfaat untuk niche Bisnis, Finansial, Karier menggunakan slang 'Cuan' (arti: Untung atau penghasilan). Tone: semangat. | C10: ='Kamus Slang'!G10 -> Cuan pertamaku dari freelance desain, ini caranya. | D10: ='Kamus Slang'!B10 -> Cuan
A11: ='Kamus Slang'!A11 -> SLG-010 | B11: ="Buat hook konten dengan fungsi "&LOWER('Kamus Slang'!F11)&" untuk niche "&'Kamus Slang'!H11&" menggunakan slang '"&'Kamus Slang'!B11&"' (arti: "&'Kamus Slang'!E11&"). Tone: "&LOWER('Kamus Slang'!I11)&"." -> Buat hook konten dengan fungsi relate/empati untuk niche Tech, Belanja, Finansial menggunakan slang 'Mendang-mending' (arti: Orang yang selalu membandingkan opsi demi yang paling hemat). Tone: jenaka. | C11: ='Kamus Slang'!G11 -> Buat kaum mendang-mending, ini perbandingan HP 2 jutaan paling jujur. | D11: ='Kamus Slang'!B11 -> Mendang-mending
A12: ='Kamus Slang'!A12 -> SLG-011 | B12: ="Buat hook konten dengan fungsi "&LOWER('Kamus Slang'!F12)&" untuk niche "&'Kamus Slang'!H12&" menggunakan slang '"&'Kamus Slang'!B12&"' (arti: "&'Kamus Slang'!E12&"). Tone: "&LOWER('Kamus Slang'!I12)&"." -> Buat hook konten dengan fungsi klaim nilai/manfaat untuk niche Affiliate, Review, Haul menggunakan slang 'Racun' (arti: Produk yang bikin penonton tergoda membeli). Tone: heboh, akrab. | C12: ='Kamus Slang'!G12 -> Siap-siap keracunan, ini 5 barang Shopee di bawah 50 ribu yang kepake banget. | D12: ='Kamus Slang'!B12 -> Racun
A13: ='Kamus Slang'!A13 -> SLG-012 | B13: ="Buat hook konten dengan fungsi "&LOWER('Kamus Slang'!F13)&" untuk niche "&'Kamus Slang'!H13&" menggunakan slang '"&'Kamus Slang'!B13&"' (arti: "&'Kamus Slang'!E13&"). Tone: "&LOWER('Kamus Slang'!I13)&"." -> Buat hook konten dengan fungsi klaim nilai/manfaat untuk niche Belanja, Finansial menggunakan slang 'Self reward' (arti: Hadiah untuk diri sendiri). Tone: hangat. | C13: ='Kamus Slang'!G13 -> Self reward tapi dompet tetap aman, ini caranya. | D13: ='Kamus Slang'!B13 -> Self reward
... A132: ='Kamus Slang'!A132 -> SLG-131 | B132: ="Buat hook konten dengan fungsi "&LOWER('Kamus Slang'!F132)&" untuk niche "&'Kamus Slang'!H132&" menggunakan slang '"&'Kamus Slang'!B132&"' (arti: "&'Kamus Slang'!E132&"). Tone: "&LOWER('Kamus Slang'!I132)&"." -> Buat hook konten dengan fungsi bikin penasaran untuk niche Kuliner, Komedi menggunakan slang 'YTTA' (arti: Yang tahu-tahu aja; info untuk kalangan tertentu). Tone: misterius. | C132: ='Kamus Slang'!G132 -> YTTA, warung ini cuma buka jam 10 malam. | D132: ='Kamus Slang'!B132 -> YTTA
